<?xml version="1.0" ?>
<!-- =================================================================================== -->
<!-- |    This document was autogenerated by xacro from j2n6s300_standalone.xacro      | -->
<!-- |    EDITING THIS FILE BY HAND IS NOT RECOMMENDED                                 | -->
<!-- =================================================================================== -->
<!-- j2n6s300 refers to jaco v2 6DOF non-spherical 3fingers -->
<robot name="j2n6s300" xmlns:body="http://playerstage.sourceforge.net/gazebo/xmlschema/#body" xmlns:controller="http://playerstage.sourceforge.net/gazebo/xmlschema/#controller" xmlns:gazebo="http://playerstage.sourceforge.net/gazebo/xmlschema/#gz" xmlns:geom="http://playerstage.sourceforge.net/gazebo/xmlschema/#geom" xmlns:interface="http://playerstage.sourceforge.net/gazebo/xmlschema/#interface" xmlns:joint="http://playerstage.sourceforge.net/gazebo/xmlschema/#joint" xmlns:model="http://playerstage.sourceforge.net/gazebo/xmlschema/#model" xmlns:physics="http://playerstage.sourceforge.net/gazebo/xmlschema/#physics" xmlns:renderable="http://playerstage.sourceforge.net/gazebo/xmlschema/#renderable" xmlns:rendering="http://playerstage.sourceforge.net/gazebo/xmlschema/#rendering" xmlns:sensor="http://playerstage.sourceforge.net/gazebo/xmlschema/#sensor" xmlns:xi="http://www.w3.org/2001/XInclude">
  <!-- links      		mesh_no
   base           		0
   shoulder       		1
   arm            		2
   forearm        		3
   wrist          		4
   arm_mico       		5
   arm_half1 (7dof)		6
   arm_half2 (7dof)		7
   wrist_spherical_1  8
   wrist_spherical_2  9

   hand 3 finger  		55
   hand_2finger   		56
   finger_proximal		57
   finger_distal      58
-->
  <!-- <xacro:include filename="$(find kinova_description)/urdf/kinova_finger_set.xacro" /> -->
  <link name="root"/>
  <!-- for gazebo -->
  <link name="world"/>
  <joint name="connect_root_and_world" type="fixed">
    <child link="root"/>
    <parent link="world"/>
    <origin rpy="0 0 0" xyz="0 0 0"/>
  </joint>
  <!-- ros_control plugin -->
  <gazebo>
    <plugin filename="libgazebo_ros_control.so" name="gazebo_ros_control">
      <robotNamespace>j2n6s300</robotNamespace>
      <robotSimType>gazebo_ros_control/DefaultRobotHWSim</robotSimType>
      <legacyModeNS>true</legacyModeNS>
    </plugin>
  </gazebo>
  <link name="j2n6s300_link_base">
    <visual>
      <geometry>
        <mesh filename="package://kinova_description/meshes/base.dae"/>
      </geometry>
      <material name="carbon_fiber">
        <color rgba="0.792156862745098 0.819607843137255 0.933333333333333 1"/>
      </material>
    </visual>
    <collision>
      <geometry>
        <mesh filename="package://kinova_description/meshes/base.dae"/>
      </geometry>
    </collision>
    <inertial>
      <mass value="0.46784"/>
      <origin rpy="0 0 0" xyz="0 0 0.1255"/>
      <inertia ixx="0.000951270861568" ixy="0" ixz="0" iyy="0.000951270861568" iyz="0" izz="0.00037427200000000004"/>
    </inertial>
  </link>
  <joint name="j2n6s300_joint_base" type="fixed">
    <parent link="root"/>
    <child link="j2n6s300_link_base"/>
    <axis xyz="0 0 0"/>
    <origin rpy="0 0 0" xyz="0 0 0"/>
    <dynamics damping="0.0" friction="0.0"/>
  </joint>
  <link name="j2n6s300_link_1">
    <visual>
      <geometry>
        <mesh filename="package://kinova_description/meshes/shoulder.dae"/>
      </geometry>
      <material name="carbon_fiber">
        <color rgba="0.792156862745098 0.819607843137255 0.933333333333333 1"/>
      </material>
    </visual>
    <visual>
      <geometry>
        <mesh filename="package://kinova_description/meshes/ring_big.dae"/>
      </geometry>
    </visual>
    <collision>
      <geometry>
        <mesh filename="package://kinova_description/meshes/shoulder.dae"/>
      </geometry>
    </collision>
    <inertial>
      <mass value="0.7477"/>
      <origin xyz="0 -0.002 -0.0605"/>
      <inertia ixx="0.0015203172520400004" ixy="0" ixz="0" iyy="0.0015203172520400004" iyz="0" izz="0.00059816"/>
    </inertial>
  </link>
  <joint name="j2n6s300_joint_1" type="continuous">
    <parent link="j2n6s300_link_base"/>
    <child link="j2n6s300_link_1"/>
    <axis xyz="0 0 1"/>
    <limit effort="40" velocity="0.6283185307179586"/>
    <origin rpy="0 3.141592653589793 0" xyz="0 0 0.15675"/>
    <dynamics damping="0.0" friction="0.0"/>
  </joint>
  <transmission name="j2n6s300_joint_1_trans">
    <type>transmission_interface/SimpleTransmission</type>
    <joint name="j2n6s300_joint_1">
      <hardwareInterface>hardware_interface/EffortJointInterface</hardwareInterface>
    </joint>
    <actuator name="j2n6s300_joint_1_actuator">
      <hardwareInterface>hardware_interface/EffortJointInterface</hardwareInterface>
      <mechanicalReduction>160</mechanicalReduction>
    </actuator>
  </transmission>
  <!--For torque sensing in simulation-->
  <gazebo reference="j2n6s300_joint_1">
    <provideFeedback>true</provideFeedback>
  </gazebo>
  <gazebo>
    <plugin filename="libgazebo_ros_ft_sensor.so" name="ft_sensor">
      <updateRate>30.0</updateRate>
      <topicName>j2n6s300_joint_1_ft_sensor_topic</topicName>
      <jointName>j2n6s300_joint_1</jointName>
    </plugin>
  </gazebo>
  <link name="j2n6s300_link_2">
    <visual>
      <geometry>
        <mesh filename="package://kinova_description/meshes/arm.dae"/>
      </geometry>
      <material name="carbon_fiber">
        <color rgba="0.792156862745098 0.819607843137255 0.933333333333333 1"/>
      </material>
    </visual>
    <visual>
      <geometry>
        <mesh filename="package://kinova_description/meshes/ring_big.dae"/>
      </geometry>
    </visual>
    <collision>
      <geometry>
        <mesh filename="package://kinova_description/meshes/arm.dae"/>
      </geometry>
    </collision>
    <inertial>
      <mass value="0.99"/>
      <origin xyz="0 -0.2065 -0.01"/>
      <inertia ixx="0.010502207990999999" ixy="0" ixz="0" iyy="0.0007920000000000001" iyz="0" izz="0.010502207990999999"/>
    </inertial>
  </link>
  <joint name="j2n6s300_joint_2" type="revolute">
    <parent link="j2n6s300_link_1"/>
    <child link="j2n6s300_link_2"/>
    <axis xyz="0 0 1"/>
    <limit effort="80" lower="0.8203047484373349" upper="5.462880558742252" velocity="0.6283185307179586"/>
    <origin rpy="-1.5707963267948966 0 3.141592653589793" xyz="0 0.0016 -0.11875"/>
    <dynamics damping="0.0" friction="0.0"/>
  </joint>
  <transmission name="j2n6s300_joint_2_trans">
    <type>transmission_interface/SimpleTransmission</type>
    <joint name="j2n6s300_joint_2">
      <hardwareInterface>hardware_interface/EffortJointInterface</hardwareInterface>
    </joint>
    <actuator name="j2n6s300_joint_2_actuator">
      <hardwareInterface>hardware_interface/EffortJointInterface</hardwareInterface>
      <mechanicalReduction>160</mechanicalReduction>
    </actuator>
  </transmission>
  <!--For torque sensing in simulation-->
  <gazebo reference="j2n6s300_joint_2">
    <provideFeedback>true</provideFeedback>
  </gazebo>
  <gazebo>
    <plugin filename="libgazebo_ros_ft_sensor.so" name="ft_sensor">
      <updateRate>30.0</updateRate>
      <topicName>j2n6s300_joint_2_ft_sensor_topic</topicName>
      <jointName>j2n6s300_joint_2</jointName>
    </plugin>
  </gazebo>
  <link name="j2n6s300_link_3">
    <visual>
      <geometry>
        <mesh filename="package://kinova_description/meshes/forearm.dae"/>
      </geometry>
      <material name="carbon_fiber">
        <color rgba="0.792156862745098 0.819607843137255 0.933333333333333 1"/>
      </material>
    </visual>
    <visual>
      <geometry>
        <mesh filename="package://kinova_description/meshes/ring_big.dae"/>
      </geometry>
    </visual>
    <collision>
      <geometry>
        <mesh filename="package://kinova_description/meshes/forearm.dae"/>
      </geometry>
    </collision>
    <inertial>
      <mass value="0.6763"/>
      <origin xyz="0 0.081 -0.0086"/>
      <inertia ixx="0.0014202243190800001" ixy="0" ixz="0" iyy="0.000304335" iyz="0" izz="0.0014202243190800001"/>
    </inertial>
  </link>
  <joint name="j2n6s300_joint_3" type="revolute">
    <parent link="j2n6s300_link_2"/>
    <child link="j2n6s300_link_3"/>
    <axis xyz="0 0 1"/>
    <limit effort="40" lower="0.33161255787892263" upper="5.951572749300664" velocity="0.6283185307179586"/>
    <origin rpy="0 3.141592653589793 0" xyz="0 -0.410 0"/>
    <dynamics damping="0.0" friction="0.0"/>
  </joint>
  <transmission name="j2n6s300_joint_3_trans">
    <type>transmission_interface/SimpleTransmission</type>
    <joint name="j2n6s300_joint_3">
      <hardwareInterface>hardware_interface/EffortJointInterface</hardwareInterface>
    </joint>
    <actuator name="j2n6s300_joint_3_actuator">
      <hardwareInterface>hardware_interface/EffortJointInterface</hardwareInterface>
      <mechanicalReduction>160</mechanicalReduction>
    </actuator>
  </transmission>
  <!--For torque sensing in simulation-->
  <gazebo reference="j2n6s300_joint_3">
    <provideFeedback>true</provideFeedback>
  </gazebo>
  <gazebo>
    <plugin filename="libgazebo_ros_ft_sensor.so" name="ft_sensor">
      <updateRate>30.0</updateRate>
      <topicName>j2n6s300_joint_3_ft_sensor_topic</topicName>
      <jointName>j2n6s300_joint_3</jointName>
    </plugin>
  </gazebo>
  <link name="j2n6s300_link_4">
    <visual>
      <geometry>
        <mesh filename="package://kinova_description/meshes/wrist.dae"/>
      </geometry>
      <material name="carbon_fiber">
        <color rgba="0.792156862745098 0.819607843137255 0.933333333333333 1"/>
      </material>
    </visual>
    <visual>
      <geometry>
        <mesh filename="package://kinova_description/meshes/ring_small.dae"/>
      </geometry>
    </visual>
    <collision>
      <geometry>
        <mesh filename="package://kinova_description/meshes/wrist.dae"/>
      </geometry>
    </collision>
    <inertial>
      <mass value="0.426367"/>
      <origin xyz="0 -0.037 -0.0642"/>
      <inertia ixx="7.734969059999999e-05" ixy="0" ixz="0" iyy="7.734969059999999e-05" iyz="0" izz="0.0001428"/>
    </inertial>
  </link>
  <joint name="j2n6s300_joint_4" type="continuous">
    <parent link="j2n6s300_link_3"/>
    <child link="j2n6s300_link_4"/>
    <axis xyz="0 0 1"/>
    <limit effort="20" velocity="0.8377580409572781"/>
    <origin rpy="-1.5707963267948966 0 3.141592653589793" xyz="0 0.2073 -0.0114"/>
    <dynamics damping="0.0" friction="0.0"/>
  </joint>
  <transmission name="j2n6s300_joint_4_trans">
    <type>transmission_interface/SimpleTransmission</type>
    <joint name="j2n6s300_joint_4">
      <hardwareInterface>hardware_interface/EffortJointInterface</hardwareInterface>
    </joint>
    <actuator name="j2n6s300_joint_4_actuator">
      <hardwareInterface>hardware_interface/EffortJointInterface</hardwareInterface>
      <mechanicalReduction>160</mechanicalReduction>
    </actuator>
  </transmission>
  <!--For torque sensing in simulation-->
  <gazebo reference="j2n6s300_joint_4">
    <provideFeedback>true</provideFeedback>
  </gazebo>
  <gazebo>
    <plugin filename="libgazebo_ros_ft_sensor.so" name="ft_sensor">
      <updateRate>30.0</updateRate>
      <topicName>j2n6s300_joint_4_ft_sensor_topic</topicName>
      <jointName>j2n6s300_joint_4</jointName>
    </plugin>
  </gazebo>
  <link name="j2n6s300_link_5">
    <visual>
      <geometry>
        <mesh filename="package://kinova_description/meshes/wrist.dae"/>
      </geometry>
      <material name="carbon_fiber">
        <color rgba="0.792156862745098 0.819607843137255 0.933333333333333 1"/>
      </material>
    </visual>
    <visual>
      <geometry>
        <mesh filename="package://kinova_description/meshes/ring_small.dae"/>
      </geometry>
    </visual>
    <collision>
      <geometry>
        <mesh filename="package://kinova_description/meshes/wrist.dae"/>
      </geometry>
    </collision>
    <inertial>
      <mass value="0.426367"/>
      <origin xyz="0 -0.037 -0.0642"/>
      <inertia ixx="7.734969059999999e-05" ixy="0" ixz="0" iyy="7.734969059999999e-05" iyz="0" izz="0.0001428"/>
    </inertial>
  </link>
  <joint name="j2n6s300_joint_5" type="continuous">
    <parent link="j2n6s300_link_4"/>
    <child link="j2n6s300_link_5"/>
    <axis xyz="0 0 1"/>
    <limit effort="20" velocity="0.8377580409572781"/>
    <origin rpy="1.0471975511965976 0 3.141592653589793" xyz="0 -0.03703 -0.06414"/>
    <dynamics damping="0.0" friction="0.0"/>
  </joint>
  <transmission name="j2n6s300_joint_5_trans">
    <type>transmission_interface/SimpleTransmission</type>
    <joint name="j2n6s300_joint_5">
      <hardwareInterface>hardware_interface/EffortJointInterface</hardwareInterface>
    </joint>
    <actuator name="j2n6s300_joint_5_actuator">
      <hardwareInterface>hardware_interface/EffortJointInterface</hardwareInterface>
      <mechanicalReduction>160</mechanicalReduction>
    </actuator>
  </transmission>
  <!--For torque sensing in simulation-->
  <gazebo reference="j2n6s300_joint_5">
    <provideFeedback>true</provideFeedback>
  </gazebo>
  <gazebo>
    <plugin filename="libgazebo_ros_ft_sensor.so" name="ft_sensor">
      <updateRate>30.0</updateRate>
      <topicName>j2n6s300_joint_5_ft_sensor_topic</topicName>
      <jointName>j2n6s300_joint_5</jointName>
    </plugin>
  </gazebo>
  <link name="j2n6s300_link_6">
    <visual>
      <geometry>
        <mesh filename="package://kinova_description/meshes/ring_small.dae"/>
      </geometry>
    </visual>
    <collision>
      <geometry>
        <mesh filename="package://kinova_description/meshes/ring_small.dae"/>
      </geometry>
    </collision>
    <inertial>
      <mass value="0.99"/>
      <origin xyz="0 0 -0.06"/>
      <inertia ixx="0.00034532361869999995" ixy="0" ixz="0" iyy="0.00034532361869999995" iyz="0" izz="0.0005815999999999999"/>
    </inertial>
  </link>
  <joint name="j2n6s300_joint_6" type="continuous">
    <parent link="j2n6s300_link_5"/>
    <child link="j2n6s300_link_6"/>
    <axis xyz="0 0 1"/>
    <limit effort="20" velocity="0.8377580409572781"/>
    <origin rpy="1.0471975511965976 0 3.141592653589793" xyz="0 -0.03703 -0.06414"/>
    <dynamics damping="0.0" friction="0.0"/>
  </joint>
  <transmission name="j2n6s300_joint_6_trans">
    <type>transmission_interface/SimpleTransmission</type>
    <joint name="j2n6s300_joint_6">
      <hardwareInterface>hardware_interface/EffortJointInterface</hardwareInterface>
    </joint>
    <actuator name="j2n6s300_joint_6_actuator">
      <hardwareInterface>hardware_interface/EffortJointInterface</hardwareInterface>
      <mechanicalReduction>160</mechanicalReduction>
    </actuator>
  </transmission>
  <!--For torque sensing in simulation-->
  <gazebo reference="j2n6s300_joint_6">
    <provideFeedback>true</provideFeedback>
  </gazebo>
  <gazebo>
    <plugin filename="libgazebo_ros_ft_sensor.so" name="ft_sensor">
      <updateRate>30.0</updateRate>
      <topicName>j2n6s300_joint_6_ft_sensor_topic</topicName>
      <jointName>j2n6s300_joint_6</jointName>
    </plugin>
  </gazebo>
  <!-- <xacro:kinova_armlink link_name="${prefix}_link_6" link_mesh="${link_6_mesh}" use_ring_mesh="true" ring_mesh="ring_small" mesh_no="${link_6_mesh_no}" use_link_mesh="false"/> -->
  <!-- <xacro:kinova_armjoint joint_name="${prefix}_joint_6" type="${joint_6_type}" parent="${prefix}_link_5" child="${prefix}_link_6" joint_axis_xyz="${joint_6_axis_xyz}" joint_origin_xyz="${joint_6_origin_xyz}" joint_origin_rpy="${joint_6_origin_rpy}" joint_lower_limit="${joint_6_lower_limit}" joint_upper_limit="${joint_6_upper_limit}" joint_velocity_limit="${joint_6_velocity_limit}" joint_torque_limit="${joint_6_torque_limit}"/> -->
  <!-- <xacro:kinova_virtual_link link_name="${prefix}_end_effector"/> -->
  <!-- <xacro:kinova_virtual_joint joint_name="${prefix}_joint_end_effector" type="${joint_end_effector_type}" parent="${prefix}_link_6" child="${prefix}_end_effector" joint_axis_xyz="${joint_end_effector_axis_xyz}" joint_origin_xyz="${joint_end_effector_origin_xyz}" joint_origin_rpy="${joint_end_effector_origin_rpy}" joint_lower_limit="0" joint_upper_limit="0"/> -->
  <!-- <xacro:kinova_3fingers link_hand="${prefix}_link_6" prefix="${prefix}_"/> -->
  <link name="assembly_base_link">
    <inertial>
      <origin rpy="0 0 0" xyz="0.024125 6.5129E-06 -1.1295E-05"/>
      <mass value="0.049705"/>
      <inertia ixx="3.9724E-05" ixy="-9.0252E-09" ixz="1.566E-08" iyy="4.0486E-05" iyz="-8.5428E-09" izz="4.0496E-05"/>
    </inertial>
    <visual>
      <origin rpy="0 0 0" xyz="0 0 0"/>
      <geometry>
        <mesh filename="package://kinova_description/assembly/meshes/final_assembly.STL" scale="0.001 0.001 0.001"/>
      </geometry>
      <material name="">
        <color rgba="1 1 1 1"/>
      </material>
    </visual>
    <collision>
      <origin rpy="0 0 0" xyz="0 0 0"/>
      <geometry>
        <mesh filename="package://kinova_description/assembly/meshes/final_assembly.STL" scale="0.001 0.001 0.001"/>
      </geometry>
    </collision>
  </link>
  <!-- 定义连接件与机械臂的关节 -->
  <joint name="arm_to_assembly" type="fixed">
    <parent link="j2n6s300_link_6"/>
    <child link="assembly_base_link"/>
    <origin rpy="0 1.5707963267948966 0.5235987755982988" xyz="0 0 0"/>
  </joint>
  <link name="palm_lower">
    <visual>
      <origin rpy="0 -0 0" xyz="-0.020095249652862544332 0.025757756134899473244 -0.034722403578460216134"/>
      <geometry>
        <mesh filename="package://kinova_description/LEAP_Hand_Sim/assets/leap_hand/palm_lower.stl"/>
      </geometry>
      <material name="palm_lower_material">
        <color rgba="0.60392156862745094426 0.14901960784313725283 0.14901960784313725283 1.0"/>
      </material>
    </visual>
    <collision>
      <origin rpy="0 -0 0" xyz="-0.020095249652862544332 0.025757756134899473244 -0.034722403578460216134"/>
      <geometry>
        <mesh filename="package://kinova_description/LEAP_Hand_Sim/assets/leap_hand/palm_lower.stl"/>
      </geometry>
    </collision>
    <inertial>
      <origin rpy="0 0 0" xyz="0 0 0"/>
      <mass value="0.237"/>
      <inertia ixx="0.000354094" ixy="-0.000001193" ixz="-0.000002445" iyy="0.000260915" iyz="-0.000002905" izz="0.000529257"/>
    </inertial>
  </link>
  <link name="mcp_joint">
    <visual>
      <origin rpy="1.6375789613220999807e-15 -1.0210473302491019535e-30 1.7177968783327987474e-31" xyz="0.0084069022611744960438 0.0077662438597169954416 0.014657354985032912051"/>
      <geometry>
        <mesh filename="package://kinova_description/LEAP_Hand_Sim/assets/leap_hand/mcp_joint.stl"/>
      </geometry>
      <material name="mcp_joint_material">
        <color rgba="0.86666666666666669627 0.86666666666666669627 0.050980392156862744391 1.0"/>
      </material>
    </visual>
    <collision>
      <origin rpy="1.6375789613220999807e-15 -1.0210473302491019535e-30 1.7177968783327987474e-31" xyz="0.0084069022611744960438 0.0077662438597169954416 0.014657354985032912051"/>
      <geometry>
        <mesh filename="package://kinova_description/LEAP_Hand_Sim/assets/leap_hand/mcp_joint.stl"/>
      </geometry>
    </collision>
    <inertial>
      <origin rpy="0 0 0" xyz="0 0 0"/>
      <mass value="0.044"/>
      <inertia ixx="0.000011499" ixy="0.000003049" ixz="0.000000121" iyy="0.000007796" iyz="0.000000112" izz="0.000014759"/>
    </inertial>
  </link>
  <link name="pip">
    <visual>
      <origin rpy="-1.570796326794896558 -1.570796326794896336 0" xyz="0.0096433630922713280131 0.00029999999999998951117 0.00078403401041737645627"/>
      <geometry>
        <mesh filename="package://kinova_description/LEAP_Hand_Sim/assets/leap_hand/pip.stl"/>
      </geometry>
      <material name="pip_material">
        <color rgba="0.74901960784313725839 0.74901960784313725839 0.74901960784313725839 1.0"/>
      </material>
    </visual>
    <collision>
      <origin rpy="-1.570796326794896558 -1.570796326794896336 0" xyz="0.0096433630922713280131 0.00029999999999998951117 0.00078403401041737645627"/>
      <geometry>
        <mesh filename="package://kinova_description/LEAP_Hand_Sim/assets/leap_hand/pip.stl"/>
      </geometry>
    </collision>
    <inertial>
      <origin rpy="0 0 0" xyz="0 0 0"/>
      <mass value="0.032"/>
      <inertia ixx="0.000004798" ixy="0.000000012" ixz="0.000000004" iyy="0.000002862" iyz="0.000000011" izz="0.000004234"/>
    </inertial>
  </link>
  <link name="dip">
    <visual>
      <origin rpy="-3.141592653589793116 4.5075111242164408299e-32 4.4395481053923607589e-32" xyz="0.021133352895225002849 -0.0084321191467048792201 0.0097850881620952408213"/>
      <geometry>
        <mesh filename="package://kinova_description/LEAP_Hand_Sim/assets/leap_hand/dip.stl"/>
      </geometry>
      <material name="dip_material">
        <color rgba="0.86666666666666669627 0.86666666666666669627 0.050980392156862744391 1.0"/>
      </material>
    </visual>
    <collision>
      <origin rpy="-3.141592653589793116 4.5075111242164408299e-32 4.4395481053923607589e-32" xyz="0.021133352895225002849 -0.0084321191467048792201 0.0097850881620952408213"/>
      <geometry>
        <mesh filename="package://kinova_description/LEAP_Hand_Sim/assets/leap_hand/dip.stl"/>
      </geometry>
    </collision>
    <inertial>
      <origin rpy="0 0 0" xyz="0 0 0"/>
      <mass value="0.037"/>
      <inertia ixx="0.000005542" ixy="-0.000000607" ixz="-0.000000017" iyy="0.000005727" iyz="-0.000000023" izz="0.000006682"/>
    </inertial>
  </link>
  <link name="fingertip">
    <visual>
      <origin rpy="3.141592653589793116 1.1993117970061734707e-33 4.4395481053923607589e-32" xyz="0.013286424108533503169 -0.0061142383865419869249 0.014499999999999497666"/>
      <geometry>
        <mesh filename="package://kinova_description/LEAP_Hand_Sim/assets/leap_hand/fingertip.stl"/>
      </geometry>
      <material name="fingertip_material">
        <color rgba="0.86666666666666669627 0.86666666666666669627 0.050980392156862744391 1.0"/>
      </material>
    </visual>
    <collision>
      <origin rpy="3.141592653589793116 1.1993117970061734707e-33 4.4395481053923607589e-32" xyz="0.013286424108533503169 -0.0061142383865419869249 0.014499999999999497666"/>
      <geometry>
        <mesh filename="package://kinova_description/LEAP_Hand_Sim/assets/leap_hand/fingertip.stl"/>
      </geometry>
    </collision>
    <inertial>
      <origin rpy="0 0 0" xyz="0 0 0"/>
      <mass value="0.016"/>
      <inertia ixx="0.000003368" ixy="0.000000115" ixz="0" iyy="0.000001556" iyz="0" izz="0.000002863"/>
    </inertial>
  </link>
  <joint name="0" type="revolute">
    <origin rpy="-1.570796326794896558 -1.0065212660796336576e-15 1.5707963267948943376" xyz="-0.012200000000000007713 0.038099999999999994982 0.014500000000000000736"/>
    <parent link="mcp_joint"/>
    <child link="pip"/>
    <axis xyz="0 0 -1"/>
    <limit effort="0.95" lower="-1.047" upper="1.047" velocity="8.48"/>
    <joint_properties friction="0.0"/>
  </joint>
  <joint name="1" type="revolute">
    <origin rpy="1.5707963267948950037 1.5707963267948945596 0" xyz="-0.0070952496528625457958 0.023057756134899472233 -0.01872240357846021927"/>
    <parent link="palm_lower"/>
    <child link="mcp_joint"/>
    <axis xyz="0 0 -1"/>
    <limit effort="0.95" lower="-0.314" upper="2.23" velocity="8.48"/>
    <joint_properties friction="0.0"/>
  </joint>
  <joint name="2" type="revolute">
    <origin rpy="1.5707963267948958919 -1.570796326794896336 0" xyz="0.01499999999999996822 0.014299999999999904801 -0.012999999999999824196"/>
    <parent link="pip"/>
    <child link="dip"/>
    <axis xyz="0 0 -1"/>
    <limit effort="0.95" lower="-0.506" upper="1.885" velocity="8.48"/>
    <joint_properties friction="0.0"/>
  </joint>
  <joint name="3" type="revolute">
    <origin rpy="4.5935029425113685044e-17 -2.8730071914463794583e-16 4.4395481053923607589e-32" xyz="-4.0880582495572692636e-09 -0.036100004210367367397 0.00020000000000007858714"/>
    <parent link="dip"/>
    <child link="fingertip"/>
    <axis xyz="0 0 -1"/>
    <limit effort="0.95" lower="-0.366" upper="2.042" velocity="8.48"/>
    <joint_properties friction="0.0"/>
  </joint>
  <link name="mcp_joint_2">
    <visual>
      <origin rpy="1.6375789613220999807e-15 -1.0076465469034000467e-30 2.1209300131419907151e-61" xyz="0.0084069022611744960438 0.0077662438597169954416 0.014657354985032913786"/>
      <geometry>
        <mesh filename="package://kinova_description/LEAP_Hand_Sim/assets/leap_hand/mcp_joint.stl"/>
      </geometry>
      <material name="mcp_joint_material">
        <color rgba="0.86666666666666669627 0.86666666666666669627 0.050980392156862744391 1.0"/>
      </material>
    </visual>
    <collision>
      <origin rpy="1.6375789613220999807e-15 -1.0076465469034000467e-30 2.1209300131419907151e-61" xyz="0.0084069022611744960438 0.0077662438597169954416 0.014657354985032913786"/>
      <geometry>
        <mesh filename="package://kinova_description/LEAP_Hand_Sim/assets/leap_hand/mcp_joint.stl"/>
      </geometry>
    </collision>
    <inertial>
      <origin rpy="0 0 0" xyz="0 0 0"/>
      <mass value="0.044"/>
      <inertia ixx="0.000011499" ixy="0.000003049" ixz="0.000000121" iyy="0.000007796" iyz="0.000000112" izz="0.000014759"/>
    </inertial>
  </link>
  <link name="pip_2">
    <visual>
      <origin rpy="-1.570796326794896558 -1.570796326794896336 0" xyz="0.0096433630922713280131 0.00029999999999999471534 0.00078403401041737645627"/>
      <geometry>
        <mesh filename="package://kinova_description/LEAP_Hand_Sim/assets/leap_hand/pip.stl"/>
      </geometry>
      <material name="pip_material">
        <color rgba="0.74901960784313725839 0.74901960784313725839 0.74901960784313725839 1.0"/>
      </material>
    </visual>
    <collision>
      <origin rpy="-1.570796326794896558 -1.570796326794896336 0" xyz="0.0096433630922713280131 0.00029999999999999471534 0.00078403401041737645627"/>
      <geometry>
        <mesh filename="package://kinova_description/LEAP_Hand_Sim/assets/leap_hand/pip.stl"/>
      </geometry>
    </collision>
    <inertial>
      <origin rpy="0 0 0" xyz="0 0 0"/>
      <mass value="0.032"/>
      <inertia ixx="0.000004798" ixy="0.000000012" ixz="0.000000004" iyy="0.000002862" iyz="0.000000011" izz="0.000004234"/>
    </inertial>
  </link>
  <link name="dip_2">
    <visual>
      <origin rpy="-3.141592653589793116 2.1146933785271955805e-32 1.4408183216511868558e-31" xyz="0.021133352895225002849 -0.0084321191467048653423 0.0097850881620952373519"/>
      <geometry>
        <mesh filename="package://kinova_description/LEAP_Hand_Sim/assets/leap_hand/dip.stl"/>
      </geometry>
      <material name="dip_material">
        <color rgba="0.86666666666666669627 0.86666666666666669627 0.050980392156862744391 1.0"/>
      </material>
    </visual>
    <collision>
      <origin rpy="-3.141592653589793116 2.1146933785271955805e-32 1.4408183216511868558e-31" xyz="0.021133352895225002849 -0.0084321191467048653423 0.0097850881620952373519"/>
      <geometry>
        <mesh filename="package://kinova_description/LEAP_Hand_Sim/assets/leap_hand/dip.stl"/>
      </geometry>
    </collision>
    <inertial>
      <origin rpy="0 0 0" xyz="0 0 0"/>
      <mass value="0.037"/>
      <inertia ixx="0.000005542" ixy="-0.000000607" ixz="-0.000000017" iyy="0.000005727" iyz="-0.000000023" izz="0.000006682"/>
    </inertial>
  </link>
  <link name="fingertip_2">
    <visual>
      <origin rpy="3.141592653589793116 -4.3179597882835943107e-33 1.4408183216511868558e-31" xyz="0.01328642410853349623 -0.0061142383865420008027 0.014499999999999495931"/>
      <geometry>
        <mesh filename="package://kinova_description/LEAP_Hand_Sim/assets/leap_hand/fingertip.stl"/>
      </geometry>
      <material name="fingertip_material">
        <color rgba="0.86666666666666669627 0.86666666666666669627 0.050980392156862744391 1.0"/>
      </material>
    </visual>
    <collision>
      <origin rpy="3.141592653589793116 -4.3179597882835943107e-33 1.4408183216511868558e-31" xyz="0.01328642410853349623 -0.0061142383865420008027 0.014499999999999495931"/>
      <geometry>
        <mesh filename="package://kinova_description/LEAP_Hand_Sim/assets/leap_hand/fingertip.stl"/>
      </geometry>
    </collision>
    <inertial>
      <origin rpy="0 0 0" xyz="0 0 0"/>
      <mass value="0.016"/>
      <inertia ixx="0.000003368" ixy="0.000000115" ixz="0" iyy="0.000001556" iyz="0" izz="0.000002863"/>
    </inertial>
  </link>
  <joint name="4" type="revolute">
    <origin rpy="-1.570796326794896558 -1.0065212760057939085e-15 1.5707963267948943376" xyz="-0.012200000000000019856 0.038099999999999981104 0.01450000000000000594"/>
    <parent link="mcp_joint_2"/>
    <child link="pip_2"/>
    <axis xyz="0 0 -1"/>
    <limit effort="0.95" lower="-1.047" upper="1.047" velocity="8.48"/>
    <joint_properties friction="0.0"/>
  </joint>
  <joint name="5" type="revolute">
    <origin rpy="1.570796326794896558 1.570796326794896558 0" xyz="-0.0070952496528625388569 -0.022392243865100525113 -0.018722403578460229678"/>
    <parent link="palm_lower"/>
    <child link="mcp_joint_2"/>
    <axis xyz="0 0 -1"/>
    <limit effort="0.95" lower="-0.314" upper="2.23" velocity="8.48"/>
    <joint_properties friction="0.0"/>
  </joint>
  <joint name="6" type="revolute">
    <origin rpy="1.5707963267948958919 -1.570796326794896336 0" xyz="0.014999999999999975159 0.014300000000000000211 -0.013000000000000018485"/>
    <parent link="pip_2"/>
    <child link="dip_2"/>
    <axis xyz="0 0 -1"/>
    <limit effort="0.95" lower="-0.506" upper="1.885" velocity="8.48"/>
    <joint_properties friction="0.0"/>
  </joint>
  <joint name="7" type="revolute">
    <origin rpy="4.5935029425113654229e-17 -2.8730071914463794583e-16 1.4408183216511868558e-31" xyz="1.0061396160665481148e-16 -0.036099999999999854428 0.00020000000000007858714"/>
    <parent link="dip_2"/>
    <child link="fingertip_2"/>
    <axis xyz="0 0 -1"/>
    <limit effort="0.95" lower="-0.366" upper="2.042" velocity="8.48"/>
    <joint_properties friction="0.0"/>
  </joint>
  <link name="mcp_joint_3">
    <visual>
      <origin rpy="1.6375789613220999807e-15 -1.0059504988632626953e-30 5.729641584552035421e-32" xyz="0.0084069022611744995133 0.0077662438597169963089 0.014657354985032913786"/>
      <geometry>
        <mesh filename="package://kinova_description/LEAP_Hand_Sim/assets/leap_hand/mcp_joint.stl"/>
      </geometry>
      <material name="mcp_joint_material">
        <color rgba="0.86666666666666669627 0.86666666666666669627 0.050980392156862744391 1.0"/>
      </material>
    </visual>
    <collision>
      <origin rpy="1.6375789613220999807e-15 -1.0059504988632626953e-30 5.729641584552035421e-32" xyz="0.0084069022611744995133 0.0077662438597169963089 0.014657354985032913786"/>
      <geometry>
        <mesh filename="package://kinova_description/LEAP_Hand_Sim/assets/leap_hand/mcp_joint.stl"/>
      </geometry>
    </collision>
    <inertial>
      <origin rpy="0 0 0" xyz="0 0 0"/>
      <mass value="0.044"/>
      <inertia ixx="0.000011499" ixy="0.000003049" ixz="0.000000121" iyy="0.000007796" iyz="0.000000112" izz="0.000014759"/>
    </inertial>
  </link>
  <link name="pip_3">
    <visual>
      <origin rpy="-1.570796326794896558 -1.570796326794896336 0" xyz="0.0096433630922713314826 0.00029999999999998083755 0.00078403401041737645627"/>
      <geometry>
        <mesh filename="package://kinova_description/LEAP_Hand_Sim/assets/leap_hand/pip.stl"/>
      </geometry>
      <material name="pip_material">
        <color rgba="0.74901960784313725839 0.74901960784313725839 0.74901960784313725839 1.0"/>
      </material>
    </visual>
    <collision>
      <origin rpy="-1.570796326794896558 -1.570796326794896336 0" xyz="0.0096433630922713314826 0.00029999999999998083755 0.00078403401041737645627"/>
      <geometry>
        <mesh filename="package://kinova_description/LEAP_Hand_Sim/assets/leap_hand/pip.stl"/>
      </geometry>
    </collision>
    <inertial>
      <origin rpy="0 0 0" xyz="0 0 0"/>
      <mass value="0.032"/>
      <inertia ixx="0.000004798" ixy="0.000000012" ixz="0.000000004" iyy="0.000002862" iyz="0.000000011" izz="0.000004234"/>
    </inertial>
  </link>
  <link name="dip_3">
    <visual>
      <origin rpy="-3.141592653589793116 -1.4095651113919093005e-33 1.5565411607615035382e-32" xyz="0.021133352895225006318 -0.0084321191467048653423 0.0097850881620952373519"/>
      <geometry>
        <mesh filename="package://kinova_description/LEAP_Hand_Sim/assets/leap_hand/dip.stl"/>
      </geometry>
      <material name="dip_material">
        <color rgba="0.86666666666666669627 0.86666666666666669627 0.050980392156862744391 1.0"/>
      </material>
    </visual>
    <collision>
      <origin rpy="-3.141592653589793116 -1.4095651113919093005e-33 1.5565411607615035382e-32" xyz="0.021133352895225006318 -0.0084321191467048653423 0.0097850881620952373519"/>
      <geometry>
        <mesh filename="package://kinova_description/LEAP_Hand_Sim/assets/leap_hand/dip.stl"/>
      </geometry>
    </collision>
    <inertial>
      <origin rpy="0 0 0" xyz="0 0 0"/>
      <mass value="0.037"/>
      <inertia ixx="0.000005542" ixy="-0.000000607" ixz="-0.000000017" iyy="0.000005727" iyz="-0.000000023" izz="0.000006682"/>
    </inertial>
  </link>
  <link name="fingertip_3">
    <visual>
      <origin rpy="3.141592653589793116 8.6170716950575402125e-33 1.5565411607615035382e-32" xyz="0.013286424108533501434 -0.0061142383865419869249 0.0144999999999994994"/>
      <geometry>
        <mesh filename="package://kinova_description/LEAP_Hand_Sim/assets/leap_hand/fingertip.stl"/>
      </geometry>
      <material name="fingertip_material">
        <color rgba="0.86666666666666669627 0.86666666666666669627 0.050980392156862744391 1.0"/>
      </material>
    </visual>
    <collision>
      <origin rpy="3.141592653589793116 8.6170716950575402125e-33 1.5565411607615035382e-32" xyz="0.013286424108533501434 -0.0061142383865419869249 0.0144999999999994994"/>
      <geometry>
        <mesh filename="package://kinova_description/LEAP_Hand_Sim/assets/leap_hand/fingertip.stl"/>
      </geometry>
    </collision>
    <inertial>
      <origin rpy="0 0 0" xyz="0 0 0"/>
      <mass value="0.016"/>
      <inertia ixx="0.000003368" ixy="0.000000115" ixz="0" iyy="0.000001556" iyz="0" izz="0.000002863"/>
    </inertial>
  </link>
  <joint name="8" type="revolute">
    <origin rpy="-1.570796326794896558 -1.0065212660796360242e-15 1.5707963267948943376" xyz="-0.012200000000000004244 0.038100000000000001921 0.014499999999999999001"/>
    <parent link="mcp_joint_3"/>
    <child link="pip_3"/>
    <axis xyz="0 0 -1"/>
    <limit effort="0.95" lower="-1.047" upper="1.047" velocity="8.48"/>
    <joint_properties friction="0.0"/>
  </joint>
  <joint name="9" type="revolute">
    <origin rpy="1.5707963267948950037 1.5707963267948945596 0" xyz="-0.0070952454426398371343 -0.067842243865100515521 -0.018722407666402932774"/>
    <parent link="palm_lower"/>
    <child link="mcp_joint_3"/>
    <axis xyz="0 0 -1"/>
    <limit effort="0.95" lower="-0.314" upper="2.23" velocity="8.48"/>
    <joint_properties friction="0.0"/>
  </joint>
  <joint name="10" type="revolute">
    <origin rpy="1.5707963267948958919 -1.570796326794896336 0" xyz="0.014999999999999971689 0.014299999999999951639 -0.012999999999999959505"/>
    <parent link="pip_3"/>
    <child link="dip_3"/>
    <axis xyz="0 0 -1"/>
    <limit effort="0.95" lower="-0.506" upper="1.885" velocity="8.48"/>
    <joint_properties friction="0.0"/>
  </joint>
  <joint name="11" type="revolute">
    <origin rpy="4.5935029425113685044e-17 -2.8730071914463799514e-16 1.5565411607615035382e-32" xyz="9.7144514654701197287e-17 -0.036099999999999868305 0.00020000000000007511769"/>
    <parent link="dip_3"/>
    <child link="fingertip_3"/>
    <axis xyz="0 0 -1"/>
    <limit effort="0.95" lower="-0.366" upper="2.042" velocity="8.48"/>
    <joint_properties friction="0.0"/>
  </joint>
  <link name="pip_4">
    <visual>
      <origin rpy="-1.570796326794896558 -1.570796326794896336 0" xyz="-0.0053566369077286714317 0.00029999999999999991951 0.00078403401041737819099"/>
      <geometry>
        <mesh filename="package://kinova_description/LEAP_Hand_Sim/assets/leap_hand/pip.stl"/>
      </geometry>
      <material name="pip_material">
        <color rgba="0.74901960784313725839 0.74901960784313725839 0.74901960784313725839 1.0"/>
      </material>
    </visual>
    <collision>
      <origin rpy="-1.570796326794896558 -1.570796326794896336 0" xyz="-0.0053566369077286714317 0.00029999999999999991951 0.00078403401041737819099"/>
      <geometry>
        <mesh filename="package://kinova_description/LEAP_Hand_Sim/assets/leap_hand/pip.stl"/>
      </geometry>
    </collision>
    <inertial>
      <origin rpy="0 0 0" xyz="0 0 0"/>
      <mass value="0.032"/>
      <inertia ixx="0.000004798" ixy="0.000000012" ixz="0.000000004" iyy="0.000002862" iyz="0.000000011" izz="0.000004234"/>
    </inertial>
  </link>
  <link name="thumb_pip">
    <visual>
      <origin rpy="1.570796326794896558 1.6050198443300152637e-46 -3.9204996250525192755e-59" xyz="0.011961920770611186859 -5.3082538364890297089e-16 -0.015852648956664199681"/>
      <geometry>
        <mesh filename="package://kinova_description/LEAP_Hand_Sim/assets/leap_hand/thumb_pip.stl"/>
      </geometry>
      <material name="thumb_pip_material">
        <color rgba="0.86666666666666669627 0.86666666666666669627 0.050980392156862744391 1.0"/>
      </material>
    </visual>
    <collision>
      <origin rpy="1.570796326794896558 1.6050198443300152637e-46 -3.9204996250525192755e-59" xyz="0.011961920770611186859 -5.3082538364890297089e-16 -0.015852648956664199681"/>
      <geometry>
        <mesh filename="package://kinova_description/LEAP_Hand_Sim/assets/leap_hand/thumb_pip.stl"/>
      </geometry>
    </collision>
    <inertial>
      <origin rpy="0 0 0" xyz="0 0 0"/>
      <mass value="0.003"/>
      <inertia ixx="0.000000593" ixy="0" ixz="0" iyy="0.000000549" iyz="0" izz="0.000000224"/>
    </inertial>
  </link>
  <link name="thumb_dip">
    <visual>
      <origin rpy="1.9428902930940098942e-16 3.2751579226442200773e-15 1.1123758529657360012e-46" xyz="0.043968715707239175439 0.057952952973709198625 -0.0086286764493694757122"/>
      <geometry>
        <mesh filename="package://kinova_description/LEAP_Hand_Sim/assets/leap_hand/thumb_dip.stl"/>
      </geometry>
      <material name="thumb_dip_material">
        <color rgba="0.86666666666666669627 0.86666666666666669627 0.050980392156862744391 1.0"/>
      </material>
    </visual>
    <collision>
      <origin rpy="1.9428902930940098942e-16 3.2751579226442200773e-15 1.1123758529657360012e-46" xyz="0.043968715707239175439 0.057952952973709198625 -0.0086286764493694757122"/>
      <geometry>
        <mesh filename="package://kinova_description/LEAP_Hand_Sim/assets/leap_hand/thumb_dip.stl"/>
      </geometry>
    </collision>
    <inertial>
      <origin rpy="0 0 0" xyz="0 0 0"/>
      <mass value="0.038"/>
      <inertia ixx="0.000008474" ixy="0.000000241" ixz="0.000000026" iyy="0.000003841" iyz="0.000000025" izz="0.000007679"/>
    </inertial>
  </link>
  <link name="thumb_fingertip">
    <visual>
      <origin rpy="4.3790577010156367543e-47 -3.3306690738754701143e-16 1.2042408677791935383e-46" xyz="0.062559538462667388381 0.078459682911396988469 0.048992911807332215068"/>
      <geometry>
        <mesh filename="package://kinova_description/LEAP_Hand_Sim/assets/leap_hand/thumb_fingertip.stl"/>
      </geometry>
      <material name="thumb_fingertip_material">
        <color rgba="0.60392156862745094426 0.14901960784313725283 0.14901960784313725283 1.0"/>
      </material>
    </visual>
    <collision>
      <origin rpy="4.3790577010156367543e-47 -3.3306690738754701143e-16 1.2042408677791935383e-46" xyz="0.062559538462667388381 0.078459682911396988469 0.048992911807332215068"/>
      <geometry>
        <mesh filename="package://kinova_description/LEAP_Hand_Sim/assets/leap_hand/thumb_fingertip.stl"/>
      </geometry>
    </collision>
    <inertial>
      <origin rpy="0 0 0" xyz="0 0 0"/>
      <mass value="0.049"/>
      <inertia ixx="0.000020372" ixy="-0.000000489" ixz="-0.00000003" iyy="0.000004336" iyz="-0.000000097" izz="0.000019845"/>
    </inertial>
  </link>
  <joint name="12" type="revolute">
    <origin rpy="-8.2381766464939424156e-17 1.5707963267948956698 0" xyz="-0.069395249652862533996 -0.0012422438651005258004 -0.021622403578460215601"/>
    <parent link="palm_lower"/>
    <child link="pip_4"/>
    <axis xyz="0 0 -1"/>
    <limit effort="0.95" lower="-0.349" upper="2.094" velocity="8.48"/>
    <joint_properties friction="0.0"/>
  </joint>
  <joint name="13" type="revolute">
    <origin rpy="1.5707963267948958919 -1.570796326794896336 0" xyz="-2.7755575615628913511e-17 0.014300000000000005415 -0.013000000000000011546"/>
    <parent link="pip_4"/>
    <child link="thumb_pip"/>
    <axis xyz="0 0 -1"/>
    <limit effort="0.95" lower="-0.47" upper="2.443" velocity="8.48"/>
    <joint_properties friction="0.0"/>
  </joint>
  <joint name="14" type="revolute">
    <origin rpy="-1.570796326794896558 1.6050198443300131245e-46 -1.9721522630516624601e-31" xyz="0 0.014499999999999966041 -0.017000000000000053263"/>
    <parent link="thumb_pip"/>
    <child link="thumb_dip"/>
    <axis xyz="0 0 -1"/>
    <limit effort="0.95" lower="-1.20" upper="1.90" velocity="8.48"/>
    <joint_properties friction="0.0"/>
  </joint>
  <joint name="15" type="revolute">
    <origin rpy="1.5063958491491781023e-44 5.4234187233935260503e-31 3.141592653589793116" xyz="-1.249000902703301108e-16 0.046599999999999863753 0.00019999999999997710581"/>
    <parent link="thumb_dip"/>
    <child link="thumb_fingertip"/>
    <axis xyz="0 0 -1"/>
    <limit effort="0.95" lower="-1.34" upper="1.88" velocity="8.48"/>
    <joint_properties friction="0.0"/>
  </joint>
  <!-- 定义手部与连接件的关节 -->
  <joint name="assembly_to_hand" type="fixed">
    <parent link="assembly_base_link"/>
    <child link="palm_lower"/>
    <origin rpy="-1.5707963267948966 0 1.5707963267948966" xyz="0.075 0.062 -0.03"/>
  </joint>
</robot>

